nohup: ignoring input
2023-01-31 01:23:58.559629: I tensorflow/core/platform/cpu_feature_guard.cc:193] This TensorFlow binary is optimized with oneAPI Deep Neural Network Library (oneDNN) to use the following CPU instructions in performance-critical operations:  AVX2 FMA
To enable them in other operations, rebuild TensorFlow with the appropriate compiler flags.
2023-01-31 01:24:00.478323: W tensorflow/compiler/xla/stream_executor/platform/default/dso_loader.cc:64] Could not load dynamic library 'libnvinfer.so.7'; dlerror: libnvinfer.so.7: cannot open shared object file: No such file or directory
2023-01-31 01:24:00.478565: W tensorflow/compiler/xla/stream_executor/platform/default/dso_loader.cc:64] Could not load dynamic library 'libnvinfer_plugin.so.7'; dlerror: libnvinfer_plugin.so.7: cannot open shared object file: No such file or directory
2023-01-31 01:24:00.478585: W tensorflow/compiler/tf2tensorrt/utils/py_utils.cc:38] TF-TRT Warning: Cannot dlopen some TensorRT libraries. If you would like to use Nvidia GPU with TensorRT, please make sure the missing libraries mentioned above are installed properly.
[32m[I 2023-01-31 01:24:04,124][0m A new study created in memory with name: no-name-f5852e20-6bea-446c-9c2c-29d9e8aae178[0m
[33m[W 2023-01-31 01:24:04,152][0m Trial 0 failed with parameters: {'max_depth': 7, 'learning_rate': 0.044635901521768134, 'colsample_bytree': 0.49279757672456204, 'subsample': 0.6394633936788147, 'alpha': 0.02938027938703535, 'lambda': 2.5348407664333426e-07, 'gamma': 3.3323645788192616e-08, 'min_child_weight': 539.948440978743} because of the following error: KeyError("None of [Int64Index([2, 3, 4, 5, 6, 7, 8, 9], dtype='int64')] are in the [index]").[0m
Traceback (most recent call last):
  File "/home/kevin/anaconda3/envs/gptchem/lib/python3.9/site-packages/optuna/study/_optimize.py", line 200, in _run_trial
    value_or_values = func(trial)
  File "/home/kevin/Documents/gptchem/src/gptchem/models/xgboost.py", line 182, in <lambda>
    lambda trial: objective(
  File "/home/kevin/Documents/gptchem/src/gptchem/models/xgboost.py", line 166, in objective
    y_A, y_B = y_values[train_index], y_values[test_index]
  File "/home/kevin/anaconda3/envs/gptchem/lib/python3.9/site-packages/pandas/core/series.py", line 984, in __getitem__
    return self._get_with(key)
  File "/home/kevin/anaconda3/envs/gptchem/lib/python3.9/site-packages/pandas/core/series.py", line 1019, in _get_with
    return self.loc[key]
  File "/home/kevin/anaconda3/envs/gptchem/lib/python3.9/site-packages/pandas/core/indexing.py", line 967, in __getitem__
    return self._getitem_axis(maybe_callable, axis=axis)
  File "/home/kevin/anaconda3/envs/gptchem/lib/python3.9/site-packages/pandas/core/indexing.py", line 1191, in _getitem_axis
    return self._getitem_iterable(key, axis=axis)
  File "/home/kevin/anaconda3/envs/gptchem/lib/python3.9/site-packages/pandas/core/indexing.py", line 1132, in _getitem_iterable
    keyarr, indexer = self._get_listlike_indexer(key, axis)
  File "/home/kevin/anaconda3/envs/gptchem/lib/python3.9/site-packages/pandas/core/indexing.py", line 1327, in _get_listlike_indexer
    keyarr, indexer = ax._get_indexer_strict(key, axis_name)
  File "/home/kevin/anaconda3/envs/gptchem/lib/python3.9/site-packages/pandas/core/indexes/base.py", line 5782, in _get_indexer_strict
    self._raise_if_missing(keyarr, indexer, axis_name)
  File "/home/kevin/anaconda3/envs/gptchem/lib/python3.9/site-packages/pandas/core/indexes/base.py", line 5842, in _raise_if_missing
    raise KeyError(f"None of [{key}] are in the [{axis_name}]")
KeyError: "None of [Int64Index([2, 3, 4, 5, 6, 7, 8, 9], dtype='int64')] are in the [index]"
[33m[W 2023-01-31 01:24:04,175][0m Trial 0 failed with value None.[0m
Traceback (most recent call last):
  File "/home/kevin/Documents/gptchem/experiments/04_regression/polymers/run_experiments.py", line 77, in <module>
    train_test_model(num_train_points, seed + 4354)
  File "/home/kevin/Documents/gptchem/experiments/04_regression/polymers/run_experiments.py", line 47, in train_test_model
    baseline = train_test_polymer_regression_baseline(
  File "/home/kevin/Documents/gptchem/src/gptchem/baselines/polymer.py", line 88, in train_test_polymer_regression_baseline
    baseline.tune(X_train, y_train)
  File "/home/kevin/Documents/gptchem/src/gptchem/models/xgboost.py", line 181, in tune
    study.optimize(
  File "/home/kevin/anaconda3/envs/gptchem/lib/python3.9/site-packages/optuna/study/study.py", line 425, in optimize
    _optimize(
  File "/home/kevin/anaconda3/envs/gptchem/lib/python3.9/site-packages/optuna/study/_optimize.py", line 66, in _optimize
    _optimize_sequential(
  File "/home/kevin/anaconda3/envs/gptchem/lib/python3.9/site-packages/optuna/study/_optimize.py", line 163, in _optimize_sequential
    frozen_trial = _run_trial(study, func, catch)
  File "/home/kevin/anaconda3/envs/gptchem/lib/python3.9/site-packages/optuna/study/_optimize.py", line 251, in _run_trial
    raise func_err
  File "/home/kevin/anaconda3/envs/gptchem/lib/python3.9/site-packages/optuna/study/_optimize.py", line 200, in _run_trial
    value_or_values = func(trial)
  File "/home/kevin/Documents/gptchem/src/gptchem/models/xgboost.py", line 182, in <lambda>
    lambda trial: objective(
  File "/home/kevin/Documents/gptchem/src/gptchem/models/xgboost.py", line 166, in objective
    y_A, y_B = y_values[train_index], y_values[test_index]
  File "/home/kevin/anaconda3/envs/gptchem/lib/python3.9/site-packages/pandas/core/series.py", line 984, in __getitem__
    return self._get_with(key)
  File "/home/kevin/anaconda3/envs/gptchem/lib/python3.9/site-packages/pandas/core/series.py", line 1019, in _get_with
    return self.loc[key]
  File "/home/kevin/anaconda3/envs/gptchem/lib/python3.9/site-packages/pandas/core/indexing.py", line 967, in __getitem__
    return self._getitem_axis(maybe_callable, axis=axis)
  File "/home/kevin/anaconda3/envs/gptchem/lib/python3.9/site-packages/pandas/core/indexing.py", line 1191, in _getitem_axis
    return self._getitem_iterable(key, axis=axis)
  File "/home/kevin/anaconda3/envs/gptchem/lib/python3.9/site-packages/pandas/core/indexing.py", line 1132, in _getitem_iterable
    keyarr, indexer = self._get_listlike_indexer(key, axis)
  File "/home/kevin/anaconda3/envs/gptchem/lib/python3.9/site-packages/pandas/core/indexing.py", line 1327, in _get_listlike_indexer
    keyarr, indexer = ax._get_indexer_strict(key, axis_name)
  File "/home/kevin/anaconda3/envs/gptchem/lib/python3.9/site-packages/pandas/core/indexes/base.py", line 5782, in _get_indexer_strict
    self._raise_if_missing(keyarr, indexer, axis_name)
  File "/home/kevin/anaconda3/envs/gptchem/lib/python3.9/site-packages/pandas/core/indexes/base.py", line 5842, in _raise_if_missing
    raise KeyError(f"None of [{key}] are in the [{axis_name}]")
KeyError: "None of [Int64Index([2, 3, 4, 5, 6, 7, 8, 9], dtype='int64')] are in the [index]"
